INFO:     Started server process [10836]
INFO:     Waiting for application startup.
ERROR:    Traceback (most recent call last):
  File "C:\Users\maxig\OneDrive\바탕 화면\newsmonitor\.venv\Lib\site-packages\starlette\routing.py", line 693, in lifespan
    async with self.lifespan_context(app) as maybe_state:
  File "C:\Users\maxig\OneDrive\바탕 화면\newsmonitor\.venv\Lib\site-packages\starlette\routing.py", line 569, in __aenter__
    await self._router.startup()
  File "C:\Users\maxig\OneDrive\바탕 화면\newsmonitor\.venv\Lib\site-packages\starlette\routing.py", line 670, in startup
    await handler()
  File "C:\Users\maxig\OneDrive\바탕 화면\newsmonitor\api\server.py", line 38, in startup_event
    await connect_db()
  File "C:\Users\maxig\OneDrive\바탕 화면\newsmonitor\api\storage\pg.py", line 19, in connect_db
    _pool = await asyncpg.create_pool(dsn=await _dsn(), min_size=1, max_size=10)
            ^^^^^^^^^^^^^^^^^^^^^^^^^^^^^^^^^^^^^^^^^^^^^^^^^^^^^^^^^^^^^^^^^^^^
  File "C:\Users\maxig\OneDrive\바탕 화면\newsmonitor\.venv\Lib\site-packages\asyncpg\pool.py", line 418, in _async__init__
    await self._initialize()
  File "C:\Users\maxig\OneDrive\바탕 화면\newsmonitor\.venv\Lib\site-packages\asyncpg\pool.py", line 445, in _initialize
    await first_ch.connect()
  File "C:\Users\maxig\OneDrive\바탕 화면\newsmonitor\.venv\Lib\site-packages\asyncpg\pool.py", line 132, in connect
    self._con = await self._pool._get_new_connection()
                ^^^^^^^^^^^^^^^^^^^^^^^^^^^^^^^^^^^^^^
  File "C:\Users\maxig\OneDrive\바탕 화면\newsmonitor\.venv\Lib\site-packages\asyncpg\pool.py", line 517, in _get_new_connection
    con = await self._connect(
          ^^^^^^^^^^^^^^^^^^^^
  File "C:\Users\maxig\OneDrive\바탕 화면\newsmonitor\.venv\Lib\site-packages\asyncpg\connection.py", line 2421, in connect
    return await connect_utils._connect(
           ^^^^^^^^^^^^^^^^^^^^^^^^^^^^^
  File "C:\Users\maxig\OneDrive\바탕 화면\newsmonitor\.venv\Lib\site-packages\asyncpg\connect_utils.py", line 1075, in _connect
    raise last_error or exceptions.TargetServerAttributeNotMatched(
  File "C:\Users\maxig\OneDrive\바탕 화면\newsmonitor\.venv\Lib\site-packages\asyncpg\connect_utils.py", line 1049, in _connect
    conn = await _connect_addr(
           ^^^^^^^^^^^^^^^^^^^^
  File "C:\Users\maxig\OneDrive\바탕 화면\newsmonitor\.venv\Lib\site-packages\asyncpg\connect_utils.py", line 886, in _connect_addr
    return await __connect_addr(params, True, *args)
           ^^^^^^^^^^^^^^^^^^^^^^^^^^^^^^^^^^^^^^^^^
  File "C:\Users\maxig\OneDrive\바탕 화면\newsmonitor\.venv\Lib\site-packages\asyncpg\connect_utils.py", line 931, in __connect_addr
    tr, pr = await connector
             ^^^^^^^^^^^^^^^
  File "C:\Users\maxig\OneDrive\바탕 화면\newsmonitor\.venv\Lib\site-packages\asyncpg\connect_utils.py", line 802, in _create_ssl_connection
    tr, pr = await loop.create_connection(
             ^^^^^^^^^^^^^^^^^^^^^^^^^^^^^
  File "C:\Program Files\WindowsApps\PythonSoftwareFoundation.Python.3.11_3.11.2544.0_x64__qbz5n2kfra8p0\Lib\asyncio\base_events.py", line 1091, in create_connection
    raise exceptions[0]
  File "C:\Program Files\WindowsApps\PythonSoftwareFoundation.Python.3.11_3.11.2544.0_x64__qbz5n2kfra8p0\Lib\asyncio\base_events.py", line 1070, in create_connection
    sock = await self._connect_sock(
           ^^^^^^^^^^^^^^^^^^^^^^^^^
  File "C:\Program Files\WindowsApps\PythonSoftwareFoundation.Python.3.11_3.11.2544.0_x64__qbz5n2kfra8p0\Lib\asyncio\base_events.py", line 974, in _connect_sock
    await self.sock_connect(sock, address)
  File "C:\Program Files\WindowsApps\PythonSoftwareFoundation.Python.3.11_3.11.2544.0_x64__qbz5n2kfra8p0\Lib\asyncio\proactor_events.py", line 726, in sock_connect
    return await self._proactor.connect(sock, address)
           ^^^^^^^^^^^^^^^^^^^^^^^^^^^^^^^^^^^^^^^^^^^
  File "C:\Program Files\WindowsApps\PythonSoftwareFoundation.Python.3.11_3.11.2544.0_x64__qbz5n2kfra8p0\Lib\asyncio\windows_events.py", line 854, in _poll
    value = callback(transferred, key, ov)
            ^^^^^^^^^^^^^^^^^^^^^^^^^^^^^^
  File "C:\Program Files\WindowsApps\PythonSoftwareFoundation.Python.3.11_3.11.2544.0_x64__qbz5n2kfra8p0\Lib\asyncio\windows_events.py", line 641, in finish_connect
    ov.getresult()
ConnectionRefusedError: [WinError 1225] 원격 컴퓨터가 네트워크 연결을 거부했습니다

ERROR:    Application startup failed. Exiting.
